Workbook
Name ENT: Data!$X$4
Name USGS49: Data!$X$3

Sheet Data
A1: OurLabID | B1: Sample ID | C1: Analysis_Date_Time | D1: d2H of injections | E1: d2H injections St Dev | F1: d2H of Analyses | G1: d2H injections St Dev | H1: d18O of injections | I1: d18O injections St Dev | J1: M USGS49 (mg) | K1: M ENT (mg) | L1: XENT | M1: MSiO2 | N1: d18O Meas | O1: d18O Nominal | P1: (18O/16O)soln | Q1: d18O Fl | R1: Δ18O Fl | S1: MO,MTZ (g) | T1: MMTZ (g) | U1: Solb (molality)
A2: W-3 | B2: DIW Wash | C2: 45485.791 | D2: -38.83 | E2: 0.08 | F2: -38.83 | H2: -6.34 | I2: 0.01 | N2: -6.34 | W2: MT Z | X2: d18O
A3: W-36 | B3: USGS 49 | C3: 45485.993 | D3: -394.7 | E3: 0.99 | F3: -394.7 | G3: 0 | H3: -50.55 | I3: 0.07 | N3: -50.55 | W3: USGS49 | X3: -50.55 | Y3: -50.55
A4: W-36 | B4: USGS 49 | C4: 45487.153 | D4: -394.7 | E4: 0.62 | F4: -394.7 | G4: 0 | H4: -50.55 | I4: 0.04 | N4: -50.55 | W4: ENT | X4: -6.59 | Y4: -6.59
A5: W-36 | B5: USGS 49 | C5: 45488.363 | D5: -394.7 | E5: 0.65 | F5: -394.7 | G5: 0 | H5: -50.55 | I5: 0.04 | N5: -50.55
A6: W-36 | B6: USGS 49 | C6: 45489.521 | D6: -394.7 | E6: 0.58 | F6: -394.7 | G6: 0 | H6: -50.55 | I6: 0.05 | N6: -50.55 | W6: USGS49 meas | X6: USGS49
A7: W-36 | B7: USGS 49 | C7: 45490.428 | D7: -394.7 | E7: 0.66 | F7: -394.7 | G7: 0 | H7: -50.55 | I7: 0.04 | N7: -50.55 | W7: -50.55 | X7: -50.55
A8: W-36 | B8: USGS 49 | C8: 45491.589 | D8: -394.7 | E8: 0.61 | F8: -394.7 | G8: 0 | H8: -50.55 | I8: 0.03 | N8: -50.55
A9: W-36 | B9: USGS 49 | C9: 45492.8 | D9: -394.7 | E9: 0.64 | F9: -394.7 | G9: 0 | H9: -50.55 | I9: 0.04 | N9: -50.55 | W9: ENT meas | X9: ENT
A10: W-36 | B10: USGS 49 | C10: 45493.959 | D10: -394.7 | E10: 0.73 | F10: -394.7 | G10: 0 | H10: -50.55 | I10: 0.06 | N10: -50.55 | W10: -6.59 | X10: -6.59
A11: W-36 | B11: USGS 49 | C11: 45494.866 | D11: -394.7 | E11: 0.77 | F11: -394.7 | G11: 0 | H11: -50.55 | I11: 0.09 | N11: -50.55
A12: W-37 | B12: USGS 50 | C12: 45486.144 | D12: 32.8 | E12: 0.16 | F12: 32.8 | G12: 0 | H12: 4.95 | I12: 0.02 | N12: 4.95 | W12: (18O/16O)SMOW | X12: =0.0020052 -> 0.0020052
A13: W-37 | B13: USGS 50 | C13: 45487.254 | D13: 32.8 | E13: 0.4 | F13: 32.8 | G13: 0 | H13: 4.95 | I13: 0.04 | N13: 4.95
A14: W-37 | B14: USGS 50 | C14: 45488.464 | D14: 32.8 | E14: 0.43 | F14: 32.8 | G14: 0 | H14: 4.95 | I14: 0.03 | N14: 4.95
A15: W-37 | B15: USGS 50 | C15: 45489.572 | D15: 32.8 | E15: 1.03 | F15: 32.8 | G15: 0 | H15: 4.95 | I15: 0.06 | N15: 4.95
A16: W-37 | B16: USGS 50 | C16: 45490.579 | D16: 32.8 | E16: 0.18 | F16: 32.8 | G16: 0 | H16: 4.95 | I16: 0.02 | N16: 4.95
A17: W-37 | B17: USGS 50 | C17: 45491.69 | D17: 32.8 | E17: 0.37 | F17: 32.8 | G17: 0 | H17: 4.95 | I17: 0.03 | N17: 4.95
A18: W-37 | B18: USGS 50 | C18: 45492.9 | D18: 32.8 | E18: 0.31 | F18: 32.8 | G18: 0 | H18: 4.95 | I18: 0.04 | N18: 4.95
A19: W-37 | B19: USGS 50 | C19: 45494.009 | D19: 32.8 | E19: 1.04 | F19: 32.8 | G19: 0 | H19: 4.95 | I19: 0.09 | N19: 4.95
A20: W-37 | B20: USGS 50 | C20: 45495.018 | D20: 32.8 | E20: 0.14 | F20: 32.8 | G20: 0 | H20: 4.95 | I20: 0.02 | N20: 4.95
A21: W-998 | B21: DI for linearity evaluation | C21: 45485.842 | D21: -38.66 | E21: 0.04 | F21: -38.65 | G21: 0.02 | H21: -6.35 | I21: 0.03 | N21: -6.34
A22: W-998 | B22: DI for linearity evaluation | C22: 45485.892 | D22: -38.63 | E22: 0.05 | F22: -38.65 | G22: 0.02 | H22: -6.32 | I22: 0.02 | N22: -6.34
A23: W-998 | B23: DI for linearity evaluation | C23: 45485.942 | D23: -38.67 | E23: 0.04 | F23: -38.65 | G23: 0.02 | H23: -6.36 | I23: 0.01 | N23: -6.34
A24: W-2366 | B24: Zircon009 RP-1 | C24: 45486.17 | D24: -40.45 | E24: 0.13 | F24: -40.34 | G24: 0.16 | H24: -7.71 | I24: 0.03 | J24: 104.0568 | K24: 2400 | L24: =K24/(K24+J24) -> 0.95844471 | N24: -7.7 | O24: =L24*ENT+(1-L24)*USGS49 -> -8.4167704 | P24: =N24*0.001*X$12+X$12 -> 0.00198976 | Q24: =((J24+K24)*N24-K24*ENT)/J24 -> -33.301402 | R24: =Q24-USGS49 -> 17.248598 | S24: =((16/18)*(J24/1000)*Q24-(16/18)*(J24/1000)*USGS49)/4.93 -> 0.32361215 | T24: =S24*183.3/(4*16) -> 0.92684542 | U24: =1000000*T24/183.3 -> 5056.4398
A25: W-2366 | B25: Zircon009 RP-1 | C25: 45490.605 | D25: -40.22 | E25: 0.42 | F25: -40.34 | G25: 0.16 | H25: -7.69 | I25: 0.04 | J25: 104.0568 | K25: 2400 | L25: =K25/(K25+J25) -> 0.95844471 | N25: -7.7 | O25: =L25*ENT+(1-L25)*USGS49 -> -8.4167704 | P25: =N25*0.001*X$12+X$12 -> 0.00198976 | Q25: =((J25+K25)*N25-K25*ENT)/J25 -> -33.301402 | R25: =Q25-USGS49 -> 17.248598 | S25: =((16/18)*(J25/1000)*Q25-(16/18)*(J25/1000)*USGS49)/4.93 -> 0.32361215 | T25: =S25*183.3/(4*16) -> 0.92684542 | U25: =1000000*T25/183.3 -> 5056.4398
A26: W-2367 | B26: Zircon014 RP-2 | C26: 45486.22 | D26: -44.86 | E26: 0.08 | F26: -44.75 | G26: 0.16 | H26: -7.71 | I26: 0.01 | J26: =1936.391-1798.5588 -> 137.8322 | K26: =(4.3729-1.929)*1000 -> 2443.9 | L26: =K26/(K26+J26) -> 0.94661251 | N26: -7.69 | O26: =L26*ENT+(1-L26)*USGS49 -> -8.936914 | P26: =N26*0.001*X$12+X$12 -> 0.00198978 | Q26: =((J26+K26)*N26-K26*ENT)/J26 -> -27.194078 | R26: =Q26-USGS49 -> 23.355922 | S26: =((16/18)*(J26/1000)*Q26-(16/18)*(J26/1000)*USGS49)/4.93 -> 0.58042787 | T26: =S26*183.3/(4*16) -> 1.6623817 | U26: =1000000*T26/183.3 -> 9069.1855
A27: W-2367 | B27: Zircon014 RP-2 | C27: 45490.656 | D27: -44.63 | E27: 0.05 | F27: -44.75 | G27: 0.16 | H27: -7.68 | I27: 0.01 | J27: =1936.391-1798.5588 -> 137.8322 | K27: =(4.3729-1.929)*1000 -> 2443.9 | L27: =K27/(K27+J27) -> 0.94661251 | N27: -7.69 | O27: =L27*ENT+(1-L27)*USGS49 -> -8.936914 | P27: =N27*0.001*X$12+X$12 -> 0.00198978 | Q27: =((J27+K27)*N27-K27*ENT)/J27 -> -27.194078 | R27: =Q27-USGS49 -> 23.355922 | S27: =((16/18)*(J27/1000)*Q27-(16/18)*(J27/1000)*USGS49)/4.93 -> 0.58042787 | T27: =S27*183.3/(4*16) -> 1.6623817 | U27: =1000000*T27/183.3 -> 9069.1855
A28: W-2368 | B28: Zircon015 RP-3 | C28: 45486.271 | D28: -40.89 | E28: 0.03 | F28: -40.71 | G28: 0.25 | H28: -4.82 | I28: 0.02 | J28: =1995.624-1796.2349 -> 199.3891 | K28: =(4.4137-1.9956)*1000 -> 2418.1 | L28: =K28/(K28+J28) -> 0.92382429 | N28: -4.81 | O28: =L28*ENT+(1-L28)*USGS49 -> -9.9386844 | P28: =N28*0.001*X$12+X$12 -> 0.001995555 | Q28: =((J28+K28)*N28-K28*ENT)/J28 -> 16.777028 | R28: =Q28-USGS49 -> 67.327028 | S28: =((16/18)*(J28/1000)*Q28-(16/18)*(J28/1000)*USGS49)/4.93 -> 2.4204238 | T28: =S28*183.3/(4*16) -> 6.932245 | U28: =1000000*T28/183.3 -> 37819.122
A29: W-2368 | B29: Zircon015 RP-3 | C29: 45490.706 | D29: -40.54 | E29: 0.32 | F29: -40.71 | G29: 0.25 | H29: -4.8 | I29: 0.03 | J29: =1995.624-1796.2349 -> 199.3891 | K29: =(4.4137-1.9956)*1000 -> 2418.1 | L29: =K29/(K29+J29) -> 0.92382429 | N29: -4.81 | O29: =L29*ENT+(1-L29)*USGS49 -> -9.9386844 | P29: =N29*0.001*X$12+X$12 -> 0.001995555 | Q29: =((J29+K29)*N29-K29*ENT)/J29 -> 16.777028 | R29: =Q29-USGS49 -> 67.327028 | S29: =((16/18)*(J29/1000)*Q29-(16/18)*(J29/1000)*USGS49)/4.93 -> 2.4204238 | T29: =S29*183.3/(4*16) -> 6.932245 | U29: =1000000*T29/183.3 -> 37819.122
A30: W-2369 | B30: Zircon017 RP-4 | C30: 45486.321 | D30: -52.76 | E30: 0.08 | F30: -52.57 | G30: 0.27 | H30: -7.83 | I30: 0.02 | J30: =1880.3652-1810.4256 -> 69.9396 | K30: =(4.2863-1.8819)*1000 -> 2404.4 | L30: =K30/(K30+J30) -> 0.97173403 | N30: -7.83 | O30: =L30*ENT+(1-L30)*USGS49 -> -7.8325719 | P30: =N30*0.001*X$12+X$12 -> 0.0019894993 | Q30: =((J30+K30)*N30-K30*ENT)/J30 -> -50.459011 | R30: =Q30-USGS49 -> 0.090988682 | S30: =((16/18)*(J30/1000)*Q30-(16/18)*(J30/1000)*USGS49)/4.93 -> 0.00114739 | T30: =S30*183.3/(4*16) -> 0.0032861968 | U30: =1000000*T30/183.3 -> 17.927969
A31: W-2369 | B31: Zircon017 RP-4 | C31: 45490.757 | D31: -52.38 | E31: 0.31 | F31: -52.57 | G31: 0.27 | H31: -7.83 | I31: 0.06 | J31: =1880.3652-1810.4256 -> 69.9396 | K31: =(4.2863-1.8819)*1000 -> 2404.4 | L31: =K31/(K31+J31) -> 0.97173403 | N31: -7.83 | O31: =L31*ENT+(1-L31)*USGS49 -> -7.8325719 | P31: =N31*0.001*X$12+X$12 -> 0.0019894993 | Q31: =((J31+K31)*N31-K31*ENT)/J31 -> -50.459011 | R31: =Q31-USGS49 -> 0.090988682 | S31: =((16/18)*(J31/1000)*Q31-(16/18)*(J31/1000)*USGS49)/4.93 -> 0.00114739 | T31: =S31*183.3/(4*16) -> 0.0032861968 | U31: =1000000*T31/183.3 -> 17.927969
A32: W-2370 | B32: Zircon019 RP-5 | C32: 45486.372 | D32: -50.1 | E32: 0.1 | F32: -49.94 | G32: 0.24 | H32: -7.47 | I32: 0.01 | J32: =1858.196-1804.0966 -> 54.0994 | K32: 2400 | L32: =K32/(K32+J32) -> 0.9779555 | N32: -7.46 | O32: =L32*ENT+(1-L32)*USGS49 -> -7.5590763 | P32: =N32*0.001*X$12+X$12 -> 0.0019902412 | Q32: =((J32+K32)*N32-K32*ENT)/J32 -> -46.055622 | R32: =Q32-USGS49 -> 4.4943779 | S32: =((16/18)*(J32/1000)*Q32-(16/18)*(J32/1000)*USGS49)/4.93 -> 0.043839197 | T32: =S32*183.3/(4*16) -> 0.1255582 | U32: =1000000*T32/183.3 -> 684.98745
A33: W-2370 | B33: Zircon019 RP-5 | C33: 45490.807 | D33: -49.77 | E33: 0.04 | F33: -49.94 | G33: 0.24 | H33: -7.45 | I33: 0.02 | J33: =1858.196-1804.0966 -> 54.0994 | K33: 2400 | L33: =K33/(K33+J33) -> 0.9779555 | N33: -7.46 | O33: =L33*ENT+(1-L33)*USGS49 -> -7.5590763 | P33: =N33*0.001*X$12+X$12 -> 0.0019902412 | Q33: =((J33+K33)*N33-K33*ENT)/J33 -> -46.055622 | R33: =Q33-USGS49 -> 4.4943779 | S33: =((16/18)*(J33/1000)*Q33-(16/18)*(J33/1000)*USGS49)/4.93 -> 0.043839197 | T33: =S33*183.3/(4*16) -> 0.1255582 | U33: =1000000*T33/183.3 -> 684.98745
A34: W-2371 | B34: Zircon021 RP-6 | C34: 45486.422 | D34: -41.68 | E34: 0.07 | F34: -41.48 | G34: 0.28 | H34: -6.39 | I34: 0.03 | J34: =1942.906-1781.8958 -> 161.0102 | K34: 2400 | L34: =K34/(K34+J34) -> 0.9371302 | N34: -6.37 | O34: =L34*ENT+(1-L34)*USGS49 -> -9.3537564 | P34: =N34*0.001*X$12+X$12 -> 0.0019924269 | Q34: =((J34+K34)*N34-K34*ENT)/J34 -> -3.0907047 | R34: =Q34-USGS49 -> 47.459295 | S34: =((16/18)*(J34/1000)*Q34-(16/18)*(J34/1000)*USGS49)/4.93 -> 1.3777653 | T34: =S34*183.3/(4*16) -> 3.9460058 | U34: =1000000*T34/183.3 -> 21527.582 | W34: Min | X34: =MIN(R24:R48) -> 0.090988682
A35: W-2371 | B35: Zircon021 RP-6 | C35: 45490.858 | D35: -41.28 | E35: 0.12 | F35: -41.48 | G35: 0.28 | H35: -6.36 | I35: 0.01 | J35: =1942.906-1781.8958 -> 161.0102 | K35: 2400 | L35: =K35/(K35+J35) -> 0.9371302 | N35: -6.37 | O35: =L35*ENT+(1-L35)*USGS49 -> -9.3537564 | P35: =N35*0.001*X$12+X$12 -> 0.0019924269 | Q35: =((J35+K35)*N35-K35*ENT)/J35 -> -3.0907047 | R35: =Q35-USGS49 -> 47.459295 | S35: =((16/18)*(J35/1000)*Q35-(16/18)*(J35/1000)*USGS49)/4.93 -> 1.3777653 | T35: =S35*183.3/(4*16) -> 3.9460058 | U35: =1000000*T35/183.3 -> 21527.582 | W35: Mean d18O shift | X35: =AVERAGE(R24:R48) -> 24.787028
A36: W-2372 | B36: Zircon022 RP-7 | C36: 45486.473 | D36: -40.77 | E36: 0.05 | F36: -40.57 | G36: 0.29 | H36: -6.74 | I36: 0.01 | J36: =1859.917-1779.875 -> 80.042 | K36: =(4.2054-1.835)*1000 -> 2370.4 | L36: =K36/(K36+J36) -> 0.96733569 | N36: -6.72 | O36: =L36*ENT+(1-L36)*USGS49 -> -8.0259231 | P36: =N36*0.001*X$12+X$12 -> 0.0019917251 | Q36: =((J36+K36)*N36-K36*ENT)/J36 -> -10.569879 | R36: =Q36-USGS49 -> 39.980121 | S36: =((16/18)*(J36/1000)*Q36-(16/18)*(J36/1000)*USGS49)/4.93 -> 0.57698244 | T36: =S36*183.3/(4*16) -> 1.6525138 | U36: =1000000*T36/183.3 -> 9015.3506 | W36: Max | X36: =MAX(R24:R48) -> 67.327028
A37: W-2372 | B37: Zircon022 RP-7 | C37: 45490.908 | D37: -40.37 | E37: 0.05 | F37: -40.57 | G37: 0.29 | H37: -6.69 | I37: 0.02 | J37: =1859.917-1779.875 -> 80.042 | K37: =(4.2054-1.835)*1000 -> 2370.4 | L37: =K37/(K37+J37) -> 0.96733569 | N37: -6.72 | O37: =L37*ENT+(1-L37)*USGS49 -> -8.0259231 | P37: =N37*0.001*X$12+X$12 -> 0.0019917251 | Q37: =((J37+K37)*N37-K37*ENT)/J37 -> -10.569879 | R37: =Q37-USGS49 -> 39.980121 | S37: =((16/18)*(J37/1000)*Q37-(16/18)*(J37/1000)*USGS49)/4.93 -> 0.57698244 | T37: =S37*183.3/(4*16) -> 1.6525138 | U37: =1000000*T37/183.3 -> 9015.3506
A38: W-2373 | B38: Zircon010 RP-8 | C38: 45486.523 | D38: -43.12 | E38: 0.14 | F38: -42.95 | G38: 0.24 | H38: -7.77 | I38: 0.01 | J38: =1874.2572-1777.9436 -> 96.3136 | K38: 2400 | L38: =K38/(K38+J38) -> 0.96141767 | N38: -7.74 | O38: =L38*ENT+(1-L38)*USGS49 -> -8.2860793 | P38: =N38*0.001*X$12+X$12 -> 0.0019896798 | Q38: =((J38+K38)*N38-K38*ENT)/J38 -> -36.396389 | R38: =Q38-USGS49 -> 14.153611 | S38: =((16/18)*(J38/1000)*Q38-(16/18)*(J38/1000)*USGS49)/4.93 -> 0.24578503 | T38: =S38*183.3/(4*16) -> 0.70394368 | U38: =1000000*T38/183.3 -> 3840.3911
A39: W-2373 | B39: Zircon010 RP-8 | C39: 45490.959 | D39: -42.78 | E39: 0.23 | F39: -42.95 | G39: 0.24 | H39: -7.72 | I39: 0.03 | J39: =1874.2572-1777.9436 -> 96.3136 | K39: 2400 | L39: =K39/(K39+J39) -> 0.96141767 | N39: -7.74 | O39: =L39*ENT+(1-L39)*USGS49 -> -8.2860793 | P39: =N39*0.001*X$12+X$12 -> 0.0019896798 | Q39: =((J39+K39)*N39-K39*ENT)/J39 -> -36.396389 | R39: =Q39-USGS49 -> 14.153611 | S39: =((16/18)*(J39/1000)*Q39-(16/18)*(J39/1000)*USGS49)/4.93 -> 0.24578503 | T39: =S39*183.3/(4*16) -> 0.70394368 | U39: =1000000*T39/183.3 -> 3840.3911 | X39: Expt | Y39: time (d) | Z39: sqrt t | AA39: Δ18O shift | AB39: % replacement image
A40: W-2374 | B40: Zircon011 RP-9 | C40: 45486.574 | D40: -53.05 | E40: 0.09 | F40: -52.87 | G40: 0.25 | H40: -7.91 | I40: 0.02 | J40: =1901.4936-1785.9073 -> 115.5863 | K40: 2400 | L40: =K40/(K40+J40) -> 0.95405194 | N40: -7.89 | O40: =L40*ENT+(1-L40)*USGS49 -> -8.6098765 | P40: =N40*0.001*X$12+X$12 -> 0.001989379 | Q40: =((J40+K40)*N40-K40*ENT)/J40 -> -34.882818 | R40: =Q40-USGS49 -> 15.667182 | S40: =((16/18)*(J40/1000)*Q40-(16/18)*(J40/1000)*USGS49)/4.93 -> 0.32651099 | T40: =S40*183.3/(4*16) -> 0.93514787 | U40: =1000000*T40/183.3 -> 5101.7342 | X40: Z_014 | Y40: 3 | Z40: =SQRT(Y40) -> 1.7320508 | AA40: =AVERAGE(R26:R27) -> 23.355922 | AB40: 15.29
...

Sheet Ternary solutions
A1: Experiment | B1: M zir (mg)
A2: Zircon005 | B2: 80.75825 | C2: blank
A3: Zircon006 | B3: 107.3
A4: Zircon009 | B4: 138.06417
A5: Zircon010 | B5: 104.53889
A6: Zircon011 | B6: 137.29443
A7: Zircon012 | B7: 35.193324 | C7: blank
A8: Zircon014 | B8: 247.82133
A9: Zircon015 | B9: 1327.8217
A10: Zircon016 | B10: 159.34723
A11: Zircon017 | B11: 0.48477781
A12: Zircon019 | B12: 19.055129
A13: Zircon021 | B13: 654.79271
A14: Zircon022 | B14: 266.23048

Sheet Mix data
A1: Reported | E1: Rearranged
A2: =Data!B1 -> Sample ID | B2: =Data!N1 -> d18O Meas | C2: =Data!O1 -> d18O Nominal | E2: =Data!N1 -> d18O Meas | F2: =Data!O1 -> d18O Nominal
A3: =Data!B50 -> Mix 1:1 | B3: =Data!N50 -> -28.2 | C3: =Data!O50 -> -21.18472 | E3: =B3 -> -28.2 | F3: =C11 -> -28.57
A4: =Data!B51 -> Mix 1:1 | B4: =Data!N51 -> -28.2 | C4: =Data!O51 -> -21.18472 | E4: =B4 -> -28.2 | F4: =C12 -> -28.57
A5: =Data!B52 -> Mix 1:2 | B5: =Data!N52 -> -20.84 | C5: =Data!O52 -> -17.623785 | E5: =B5 -> -20.84 | F5: =C3 -> -21.18472
A6: =Data!B53 -> Mix 1:2 | B6: =Data!N53 -> -20.84 | C6: =Data!O53 -> -17.623785 | E6: =B6 -> -20.84 | F6: =C4 -> -21.18472
A7: =Data!B54 -> Mix 1:3_2 | B7: =Data!N54 -> -17.3 | C7: =Data!O54 -> -7.6621951 | E7: =B7 -> -17.3 | F7: =C$5 -> -17.623785
A8: =Data!B55 -> Mix 1:3_2 | B8: =Data!N55 -> -17.3 | C8: =Data!O55 -> -7.6621951 | E8: =B8 -> -17.3 | F8: =C$5 -> -17.623785
A9: =Data!B56 -> Mix 1:3 | B9: =Data!N56 -> -17.74 | C9: =Data!O56 -> -7.6621951 | E9: =B9 -> -17.74 | F9: =C$5 -> -17.623785
A10: =Data!B57 -> Mix 1:3 | B10: =Data!N57 -> -17.74 | C10: =Data!O57 -> -7.6621951 | E10: =B10 -> -17.74 | F10: =C$5 -> -17.623785
A11: =Data!B58 -> Mix 1:4 | B11: =Data!N58 -> -15.29 | C11: =Data!O58 -> -28.57 | E11: =B11 -> -15.29 | F11: ?
A12: =Data!B59 -> Mix 1:4 | B12: =Data!N59 -> -15.29 | C12: =Data!O59 -> -28.57 | E12: =B12 -> -15.29 | F12: ?
